Workbook
Name A: [1]추정보고서!#REF!
Name A: [2]추정보고서!#REF!
Name azdfghsgfhdgfhjdghjfhgjdghffghjfgyhjfhgjf: #REF!
Name B: [1]추정보고서!#REF!
Name B: [2]추정보고서!#REF!
Name bmc..: #REF!
Name B범위: #REF!
Name B범위: [3]BMC!$AY$22:$AY$33
Name CC: [1]추정보고서!#REF!
Name CC: [2]추정보고서!#REF!
Name CVD: [1]추정보고서!#REF!
Name CVD: [2]추정보고서!#REF!
Name D: #REF!
Name DATA: OFFSET('[4]성적서 을'!$AP$31,0,'[4]성적서 을'!$AM$22:$AM$23,5,1)
Name dd: [5]교정기록지!#REF!
Name Dut: #REF!
Name Dut: #REF!
Name E: #REF!
Name embed: #REF!
Name embed: [6]Rawdata!#REF!
Name f: #REF!
Name Fitting: OFFSET('[4]성적서 을'!$AP$31,0,'[4]성적서 을'!$AM$22:$AM$23,5,1)
Name Fittingr그래프: OFFSET('[4]성적서 을'!$AP$31,0,'[4]성적서 을'!$AM$22,5,1)
Name Fitting온도: OFFSET('[4]성적서 을'!$AP$53,0,'[4]성적서 을'!$AM$38,4,1)
Name freq: #REF!
Name freq: #REF!
Name fsdzgfdgs: #REF!
Name g: #REF!
Name gBMC: #REF!
Name gBMC: [3]BMC!$AY$22:$BB$33
Name g분동조합: #REF!
Name h: #REF!
Name i: #REF!
Name ic: '[7]Raw Data'!#REF!
Name IF: '[7]Raw Data'!#REF!
Name j: #REF!
Name jkkl: #REF!
Name KnownX: [8]기록지!$CO$14:$CO$19
Name KnownY: [8]기록지!$CP$14:$CP$19
Name lkj: #REF!
Name MZ: #REF!
Name ohm: #REF!
Name q: #REF!
Name RKSKEK: [2]추정보고서!#REF!
Name RKSKEK: #REF!
Name s: #REF!
Name sffssf: #REF!
Name SN: #REF!
Name SN: #REF!
Name SS: [9]입력1!#REF!
Name SS: [9]입력1!#REF!
Name ST: [10]표준기!$A$39:$K$156
Name ST: #REF!
Name STD: [11]표준테이블!$9:$179
Name STD: [11]표준테이블!$9:$179
Name STH: #REF!
Name STS: [9]표준기2!#REF!
Name STS: [9]표준기2!#REF!
Name t: #REF!
Name TKDRL: [12]교정기록지!#REF!

Sheet 데이터
B2: 1. 기본정보
B3: 의뢰기관 | D3: 국 | E3: 예담직업전문학교
D4: 영 | E4: yedam
B5: 주 소 | D5: 국 | E5: 대구 중구 경상감영길 2 5층
D6: 영
B7: 접수번호 | E7: BD26-0004
B8: 성적서번호 | E8: BD26-0004-0001
B9: 중분류코드 | E9: 101 | K9: 소분류코드
B10: 기기명 | D10: 국 | E10: 레이저주파수 산업용 (키사이트 테크놀로지 SP7027A)
D11: 영
B12: 제작회사 | D12: 국 | E12: 키사이트 테크놀로지
D13: 영
B14: 형식 | E14: Model SP7027A
B15: 기기번호 | E15: 20260112
B16: 자산번호
B17: 교정장소 | E17: 서울시 구로구
B18: 교정주소 | D18: 국
D19: 영
B20: 교정일자 | E20: 2026. 3. 21 | K20: 교정주기 | N20: 24
B21: 승인일자
B22: 최저/최고 온도 | E22: 11 | J22: 11 | K22: 최저/최고 습도 | N22: 4 | R22: 4
B23: 최저/최고 기압 | E23: 12 | J23: 12
B24: 교정실무자(국) | E24: 이실무 | K24: 교정실무자(영) | N24: leework
B25: 기술책임자(국) | E25: 이실무 | K25: 기술책임자(영) | N25: leework
B26: 소급성 | D26: 국
D29: 영
B36: 2. 표준장비
B37: No. | D37: 사용장비명 | I37: 제작회사 및 형식 | P37: 기기번호 | T37: 차기교정일자 | X37: 교정기관 | AC37: 비고1 | AD37: 비고2 | AE37: 비고3 | AF37: 비고4 | AG37: 비고5
B38: 1 | C38: 국
C39: 영
B40: 2 | C40: 국
C41: 영
B42: 3 | C42: 국
C43: 영
B44: 4 | C44: 국
C45: 영
B46: 5 | C46: 국
C47: 영
B48: 6 | C48: 국
C49: 영
...

Sheet 성적서(갑)(영문)
AA1: CALIBRATION CERTIFICATE
B5: #524, (Sample) Republic of Korea
AM6: Tel:012-3456-7890, Fax:012-345-6789
B7: =" "&"Certificate No : " & CY7 -> Certificate No : | BO7: Check the QR at 'http://www.naver.com'
C10: 1. Client
C12: Name | AD12: : | AE12: =CY12 -> 0
C13: Address | AD13: : | AE13: =CY13 -> 0
C15: 2. Calibration Subject
C17: Description | AD17: : | AE17: =CY17 -> 0
C18: Manufacturer and Model Name | AD18: : | AE18: =""&CY18&""&" / "&CZ18&"" -> /
C19: Serial Number | AD19: : | AE19: =CY19 -> 0
C21: 3. Date of Calibration | AD21: : | AE21: =CY21 -> 0
C23: 4. Environment Conditions
C25: Temperature | P25: : | Q25: ="" & "( " & FIXED(((CY25+CY26)/2),1) & " ± " & FIXED(((CY26-CY25)/2),1) &" ) ℃" -> ( 0.0 ± 0.0 ) ℃ | AY25: Humidity | BR25: : | BS25: ="" & "( " & FIXED(((CZ25+CZ26)/2),0) & " ± " & FIXED(((CZ26-CZ25)/2),0) &" ) % R.H." -> ( 0 ± 0 ) % R.H.
C26: Location | P26: : | Q26: =IF(CY27="고정표준실","■","□") -> □ | S26: Permanent Calibration Lab. | AT26: =IF(CY27="이동교정","■","□") -> □ | AV26: Mobile Lab. | BR26: =IF(CY27="현장교정","■","□") -> □ | BT26: On Site Calibration
E27: =IF(CY27="고정표준실",B5,데이터!E19) -> 0
C29: 5. Traceability
E30: Calibration method and /or brief description :
E32: =CY32 -> 0
E37: List of used standards/specifications
D39: Description | AH39: Manufacturer and Model | BA39: Serial Number | BS39: The due date of next Cal | CH39: Calibration Lab
D40: =IF(CY40=0,"",""&CY40) | AH40: =IF(CZ40=0,"",CZ40&" / "&DA40) | BA40: =IF(DB40=0,"",DB40) | BS40: =IF(DC40=0,"",DC40) | CH40: =IF(DD40=0,"",DD40) | DC40: =데이터!T39 | DD40: =데이터!X39 -> 0
D41: =IF(CY41=0,"",""&CY41) | AH41: =IF(CZ41=0,"",CZ41&" / "&DA41) | BA41: =IF(DB41=0,"",DB41) | BS41: =IF(DC41=0,"",DC41) | CH41: =IF(DD41=0,"",DD41) | DC41: =데이터!T41 | DD41: =데이터!X41
D42: =IF(CY42=0,"",""&CY42) | AH42: =IF(CZ42=0,"",CZ42&" / "&DA42) | BA42: =IF(DB42=0,"",DB42) | BS42: =IF(DC42=0,"",DC42) | CH42: =IF(DD42=0,"",DD42) | DC42: =데이터!T43 | DD42: =데이터!X43
D43: =IF(CY43=0,"",""&CY43) | AH43: =IF(CZ43=0,"",CZ43&" / "&DA43) | BA43: =IF(DB43=0,"",DB43) | BS43: =IF(DC43=0,"",DC43) | CH43: =IF(DD43=0,"",DD43) | DC43: =데이터!T45 | DD43: =데이터!X45
D44: =IF(CY44=0,"",""&CY44) | AH44: =IF(CZ44=0,"",CZ44&" / "&DA44) | BA44: =IF(DB44=0,"",DB44) | BS44: =IF(DC44=0,"",DC44) | CH44: =IF(DD44=0,"",DD44) | DC44: =데이터!T47 | DD44: =데이터!X47
D45: =IF(CY45=0,"",""&CY45) | AH45: =IF(CZ45=0,"",CZ45&" / "&DA45) | BA45: =IF(DB45=0,"",DB45) | BS45: =IF(DC45=0,"",DC45) | CH45: =IF(DD45=0,"",DD45) | DC45: =데이터!T49 | DD45: =데이터!X49
D46: =IF(CY46=0,"",""&CY46) | AH46: =IF(CZ46=0,"",CZ46&" / "&DA46) | BA46: =IF(DB46=0,"",DB46) | BS46: =IF(DC46=0,"",DC46) | CH46: =IF(DD46=0,"",DD46) | DC46: =데이터!T51 | DD46: =데이터!X51
D47: =IF(CY47=0,"",""&CY47) | AH47: =IF(CZ47=0,"",CZ47&" / "&DA47) | BA47: =IF(DB47=0,"",DB47) | BS47: =IF(DC47=0,"",DC47) | CH47: =IF(DD47=0,"",DD47) | DC47: =데이터!T53 | DD47: =데이터!X53
D48: =IF(CY48=0,"",""&CY48) | AH48: =IF(CZ48=0,"",CZ48&" / "&DA48) | BA48: =IF(DB48=0,"",DB48) | BS48: =IF(DC48=0,"",DC48) | CH48: =IF(DD48=0,"",DD48) | DC48: =데이터!T55 | DD48: =데이터!X55
D49: =IF(CY49=0,"",""&CY49) | AH49: =IF(CZ49=0,"",CZ49&" / "&DA49) | BA49: =IF(DB49=0,"",DB49) | BS49: =IF(DC49=0,"",DC49) | CH49: =IF(DD49=0,"",DD49) | DC49: =데이터!T57 | DD49: =데이터!X57
D50: =IF(CY50=0,"",""&CY50) | AH50: =IF(CZ50=0,"",CZ50&" / "&DA50) | BA50: =IF(DB50=0,"",DB50) | BS50: =IF(DC50=0,"",DC50) | CH50: =IF(DD50=0,"",DD50) | DC50: =데이터!T59 | DD50: =데이터!X59
D51: =IF(CY51=0,"",""&CY51) | AH51: =IF(CZ51=0,"",CZ51&" / "&DA51) | BA51: =IF(DB51=0,"",DB51) | BS51: =IF(DC51=0,"",DC51) | CH51: =IF(DD51=0,"",DD51) | DC51: =데이터!T61 | DD51: =데이터!X61
D52: =IF(CY52=0,"",""&CY52) | AH52: =IF(CZ52=0,"",CZ52&" / "&DA52) | BA52: =IF(DB52=0,"",DB52) | BS52: =IF(DC52=0,"",DC52) | CH52: =IF(DD52=0,"",DD52) | DC52: =데이터!T63 | DD52: =데이터!X63
D53: =IF(CY53=0,"",""&CY53) | AH53: =IF(CZ53=0,"",CZ53&" / "&DA53) | BA53: =IF(DB53=0,"",DB53) | BS53: =IF(DC53=0,"",DC53) | CH53: =IF(DD53=0,"",DD53) | DC53: =데이터!T65 | DD53: =데이터!X65
D54: =IF(CY54=0,"",""&CY54) | AH54: =IF(CZ54=0,"",CZ54&" / "&DA54) | BA54: =IF(DB54=0,"",DB54) | BS54: =IF(DC54=0,"",DC54) | CH54: =IF(DD54=0,"",DD54) | DC54: =데이터!T67 | DD54: =데이터!X67
C56: 6. Calibration Results | Z56: : | AB56: Refer attached file
C58: 7. Measurement Uncertainty | Z58: : | AB58: Refer attached file
E60: Affirmation | P60: Measurements performed by | BA60: Approved by
P62: Name | AB62: : | AC62: =CY62 -> 0 | BA62: Title | BN62: : | BO62: Technical Manager
...

Sheet 성적서(을)(영문)
AA1: CALIBRATION RESULTS
B5: ='성적서(갑)(영문)'!B5 -> #524, (Sample) Republic of Korea
AM6: ='성적서(갑)(영문)'!AM6 -> Tel:012-3456-7890, Fax:012-345-6789
B7: ='성적서(갑)(영문)'!B7 -> Certificate No : | BO7: Check the QR at 'http://www.naver.com'
C10: * Description | AB10: : | AE10: ='성적서(갑)(국문)'!CY17 -> 0
C12: * Manufacturer and Model Name | AB12: : | AE12: =""&'성적서(갑)(국문)'!CY18&""&" / "&'성적서(갑)(국문)'!CZ18&"" -> /
C14: * Serial Number | AB14: : | AE14: ='성적서(갑)(국문)'!CY19 -> 0
C16: * Maximum Capacity | AB16: : | AE16: =""&#REF!&" "&""&#REF!&""&"" -> #REF!
C18: * Resolution | AB18: : | AE18: =""&#REF!&" "&""&#REF!&""&"" -> #REF!
C21: 1. Eccentric Test
D23: Position | W23: Front | AP23: Rear | BI23: Left | CB23: Right
D26: Eccentric Error | W26: =#REF! -> #REF! | AP26: =#REF! -> #REF! | BI26: =#REF! -> #REF! | CB26: =#REF! -> #REF!
D30: * Used weights : | AB30: =#REF! -> #REF! | AI30: =#REF! -> #REF!
D32: * Eccentric Error = [ Front, Rear, Left, Right ]Value - Center Value
C35: 2. Linearity Test
D37: S.T.D. Conventional Mass Value | AA37: Indication Value | AX37: Correction | BU37: Meausurement Uncertainty
D40: =#REF! -> #REF! | AA40: =#REF! -> #REF! | AX40: =#REF! -> #REF! | BU40: =#REF! -> #REF!
D43: =#REF! -> #REF! | AA43: =#REF! -> #REF! | AX43: =#REF! -> #REF!
D46: =#REF! -> #REF! | AA46: =#REF! -> #REF! | AX46: =#REF! -> #REF!
D49: =#REF! -> #REF! | AA49: =#REF! -> #REF! | AX49: =#REF! -> #REF!
D52: =#REF! -> #REF! | AA52: =#REF! -> #REF! | AX52: =#REF! -> #REF!
D56: * Correction = Conventional Mass - Indication
D58: =IF(#REF!>10,CY58,'성적서(을)(영문)'!FC58) -> #REF! | CY58: ※ Meausurement Uncertainty The providing a confidence level of approximately 95 % , | FC58: ※ Meausurement Uncertainty The providing a confidence level of approximately 95 % ,
AU59: k = | AY59: =#REF! -> #REF!
D61: End.
D64: ='성적서(갑)(영문)'!CY76 -> 0

Sheet 성적서(갑)(국문)
AA1: 교 정 성 적 서 CALIBRATION CERTIFICATE
B5: 경기도 부산시 금정구
AM6: Tel:012-3456-7890, Fax:012-3456-7890 | BP6: ="* 원본확인번호 : " &CZ7&" " -> * 원본확인번호 :
B7: =" "&"성적서 번호 (Certificate No) : " & CY7 -> 성적서 번호 (Certificate No) : | BO7: www.naver.com
C10: 1. 의 뢰 자 ( Client )
C12: 기 관 명 ( Name ) | AD12: : | AE12: =CY12 -> 0
C13: 주 소 ( Address ) | AD13: : | AE13: =CY13 -> 0
C15: 2. 측 정 기 ( Calibration Subject )
C17: 기 기 명 ( Description ) | AD17: : | AE17: =CY17 -> 0
C18: 제작회사 및 형식 ( Manufacturer and Model Name ) | AO18: : | AP18: =""&CY18&""&" / "&CZ18&"" -> /
C19: 기기번호 ( Serial Number ) | AD19: : | AE19: =CY19 -> 0
C21: 3. 교정일자 ( Date of Calibration ) | AD21: : | AE21: =CY21 -> 0
C23: 4. 교정환경 ( Environment Conditions )
C25: 온 도 ( Temperature ) | Y25: : | Z25: ="" & "( " & FIXED(((CY25+CY26)/2),1) & " ± " & FIXED(((CY26-CY25)/2),1) &" ) ℃" -> ( 0.0 ± 0.0 ) ℃ | AY25: 습도 ( Humidity ) | BR25: : | BS25: ="" & "( " & FIXED(((CZ25+CZ26)/2),0) & " ± " & FIXED(((CZ26-CZ25)/2),0) &" ) % R.H." -> ( 0 ± 0 ) % R.H.
C26: 교정장소 ( Location ) | Y26: : | AA26: =IF(CY27="고정표준실","■","□") -> □ | AC26: 고정표준실(Permanent Calibration Lab.) | BC26: □ 이동교정(Mobile Lab.) | BT26: =IF(CY27="현장교정","■","□") -> □ | BV26: 현장교정(On Site Calibration)
E27: (부산시 금정구)
C29: 5. 측정표준의 소급성 ( Traceability )
E30: 교정방법 및 소급성 서술 ( Calibration method and /or brief description ) :
E32: =CY32 -> 0
E37: 교정에 사용된 표준장비 명세 ( List of used standards/specifications )
D39: 기기명 Description | AH39: 제작회사 및 형식 Manufacturer and Model | BA39: 기기번호 Serial Number | BS39: 차기교정예정일자 The due date of next Cal | CH39: 교정기관 Calibration Lab
C56: 6. 교정결과 ( Calibration Results ) | AO56: : | AR56: 교정결과 참조 ( Refer attached file )
C58: 7. 측정불확도 ( Measurement Uncertainty ) | AO58: : | AR58: 교정결과 참조 ( Refer attached file )
E60: 확 인 (Affirmation) | P60: 작성자 (Measurements performed by) | BA60: 승 인 자 (Approved by)
P62: 성 명 (Name) | AB62: : | AC62: =CY62 -> 0 | BA62: 직 위 (Title) | BN62: : | BO62: 기술책임자(정)
AR63: (서명) | BA63: 성 명 (Name) | BN63: : | BO63: =CY63 -> 0 | CG63: (서명)
B65: 위 성적서는 국제시험기관인정협력체 (International Laboratory Accreditation Cooperation) 상호인정협정 (Mutual Recognition Arrangement)
B66: 에 서명한 한국인정기구(KOLAS)로부터 공인받은 분야의 교정결과입니다.
C67: ( The above calibration certificate is the accredited calibration items by Korea Laboratory Accreditation Scheme, which signed the ILAC-MRA )
D69: 한국인정기구 인정 | AP69: =CY69 -> 0
D70: Accredited by KOLAS, Republic of Korea
C72: 테스트 샘플 확인 (인)
C73: TEST AGENT Co., Ltd.
C75: ㈜ 이 성적서는 측정기의 정밀정확도에 영향을 미치는 요소(과부하,온도,습도 등)의 급격한 변화가 발생한 경우에는 무효가 됩니다.
C76: (Note) If any significant instability or other adverse factor(overload,temperature,humidity etc.) manifests itself before, during or after calibration,
C77: it is likely to affect the validity of the calibration.

Sheet 성적서(을)(국문)
AA1: 교 정 결 과 CALIBRATION RESULTS
B5: ='성적서(갑)(국문)'!B5 -> 경기도 부산시 금정구
AM6: ='성적서(갑)(국문)'!AM6 -> Tel:012-3456-7890, Fax:012-3456-7890
B7: =" "&"성적서 번호 (Certificate No) : " & '성적서(갑)(국문)'!CY7 -> 성적서 번호 (Certificate No) : | BO7: http://www.novacal.co.kr 에서 원본확인 가능.
C10: * 기 기 명 (Description) | AO10: : | AR10: ='성적서(갑)(국문)'!CY17 -> 0
C12: * 제작회사 및 형식 (Manufacturer and Model Name) | AO12: : | AR12: =""&'성적서(갑)(국문)'!CY18&""&" / "&'성적서(갑)(국문)'!CZ18&"" -> /
C14: * 기기번호 (Serial Number) | AO14: : | AR14: ='성적서(갑)(국문)'!CY19 -> 0
C16: * 최대계량능력 ( Maximum Capacity ) | AO16: : | AR16: =""&#REF!&" "&""&#REF!&""&"" -> #REF!
C18: * 분해능 ( Resolution ) | AO18: : | AR18: =""&#REF!&" "&""&#REF!&""&"" -> #REF!
C21: 1. 편심시험 ( Eccentric Test )
D23: 측정위치 ( Position ) | W23: 전 ( Front ) | AP23: 후 ( Rear ) | BI23: 좌 ( Left ) | CB23: 우 ( Right )
D26: 편심오차 ( Eccentric Error ) | W26: =#REF! -> #REF! | AP26: =#REF! -> #REF! | BI26: =#REF! -> #REF! | CB26: =#REF! -> #REF!
D30: * 사용분동 ( Used weights ) : | AB30: =#REF! -> #REF! | AI30: =#REF! -> #REF!
D32: * 편심오차 = [ 전, 후, 좌, 우 ]값 - 중앙값 ( Eccentric Error = [ Front, Rear, Left, Right ]Value - Center Value )
C35: 2. 직선성 시험( Linearity Test )
D37: 표준분동의 상용질량값 ( S.T.D. Conventional Mass Value ) | AA37: 저울의 지시값 ( Indication Value ) | AX37: 보정값 ( Correction ) | BU37: 측정불확도 ( Meausurement Uncertainty )
D40: =#REF! -> #REF! | AA40: =#REF! -> #REF! | AX40: =#REF! -> #REF! | BU40: =#REF! -> #REF!
D43: =#REF! -> #REF! | AA43: =#REF! -> #REF! | AX43: =#REF! -> #REF!
D46: =#REF! -> #REF! | AA46: =#REF! -> #REF! | AX46: =#REF! -> #REF!
D49: =#REF! -> #REF! | AA49: =#REF! -> #REF! | AX49: =#REF! -> #REF!
D52: =#REF! -> #REF! | AA52: =#REF! -> #REF! | AX52: =#REF! -> #REF!
D56: * 보정값 ( Correction ) = 분동의 상용질량 ( Conventional Mass ) - 저울의 지시값 ( Indication )
D58: =IF(#REF!>10,CY58,'성적서(을)(국문)'!FC58) -> #REF!
BG59: k = | BK59: =#REF! -> #REF!
D62: 끝(End).
D64: ='성적서(갑)(국문)'!CY76 -> 0
